exception.fallback_message: '未知错误！'
